[2022-10-21 16:52:21,664] {taskinstance.py:1179} INFO - Dependencies all met for <TaskInstance: Lead_scoring_training_pipeline.training_model manual__2022-10-21T16:50:58.462830+00:00 [queued]>
[2022-10-21 16:52:21,669] {taskinstance.py:1179} INFO - Dependencies all met for <TaskInstance: Lead_scoring_training_pipeline.training_model manual__2022-10-21T16:50:58.462830+00:00 [queued]>
[2022-10-21 16:52:21,669] {taskinstance.py:1376} INFO - 
--------------------------------------------------------------------------------
[2022-10-21 16:52:21,669] {taskinstance.py:1377} INFO - Starting attempt 2 of 2
[2022-10-21 16:52:21,669] {taskinstance.py:1378} INFO - 
--------------------------------------------------------------------------------
[2022-10-21 16:52:21,677] {taskinstance.py:1397} INFO - Executing <Task(PythonOperator): training_model> on 2022-10-21 16:50:58.462830+00:00
[2022-10-21 16:52:21,685] {standard_task_runner.py:52} INFO - Started process 5585 to run task
[2022-10-21 16:52:21,691] {standard_task_runner.py:79} INFO - Running: ['airflow', 'tasks', 'run', 'Lead_scoring_training_pipeline', 'training_model', 'manual__2022-10-21T16:50:58.462830+00:00', '--job-id', '72', '--raw', '--subdir', 'DAGS_FOLDER/Lead_scoring_training_pipeline/.ipynb_checkpoints/lead_scoring_training_pipeline-checkpoint.py', '--cfg-path', '/tmp/tmpx2g1u0nq', '--error-file', '/tmp/tmppqyniwxl']
[2022-10-21 16:52:21,692] {standard_task_runner.py:80} INFO - Job 72: Subtask training_model
[2022-10-21 16:52:21,733] {task_command.py:371} INFO - Running <TaskInstance: Lead_scoring_training_pipeline.training_model manual__2022-10-21T16:50:58.462830+00:00 [running]> on host 2e24bcea55eb
[2022-10-21 16:52:21,779] {taskinstance.py:1589} INFO - Exporting the following env vars:
AIRFLOW_CTX_DAG_OWNER=airflow
AIRFLOW_CTX_DAG_ID=Lead_scoring_training_pipeline
AIRFLOW_CTX_TASK_ID=training_model
AIRFLOW_CTX_EXECUTION_DATE=2022-10-21T16:50:58.462830+00:00
AIRFLOW_CTX_TRY_NUMBER=2
AIRFLOW_CTX_DAG_RUN_ID=manual__2022-10-21T16:50:58.462830+00:00
[2022-10-21 16:52:23,338] {connectionpool.py:780} WARNING - Retrying (Retry(total=4, connect=4, read=5, redirect=5, status=5)) after connection broken by 'NewConnectionError('<urllib3.connection.HTTPConnection object at 0x7f43ea25de80>: Failed to establish a new connection: [Errno 111] Connection refused')': /api/2.0/mlflow/runs/create
[2022-10-21 16:52:27,343] {connectionpool.py:780} WARNING - Retrying (Retry(total=3, connect=3, read=5, redirect=5, status=5)) after connection broken by 'NewConnectionError('<urllib3.connection.HTTPConnection object at 0x7f43ea27eb20>: Failed to establish a new connection: [Errno 111] Connection refused')': /api/2.0/mlflow/runs/create
[2022-10-21 16:52:35,353] {connectionpool.py:780} WARNING - Retrying (Retry(total=2, connect=2, read=5, redirect=5, status=5)) after connection broken by 'NewConnectionError('<urllib3.connection.HTTPConnection object at 0x7f43ea27ea60>: Failed to establish a new connection: [Errno 111] Connection refused')': /api/2.0/mlflow/runs/create
[2022-10-21 16:52:36,606] {process_utils.py:125} INFO - Sending Signals.SIGTERM to group 5585. PIDs of all processes in the group: [5585]
[2022-10-21 16:52:36,607] {process_utils.py:80} INFO - Sending the signal Signals.SIGTERM to group 5585
[2022-10-21 16:52:36,607] {taskinstance.py:1561} ERROR - Received SIGTERM. Terminating subprocesses.
[2022-10-21 16:52:36,608] {taskinstance.py:1909} ERROR - Task failed with exception
Traceback (most recent call last):
  File "/opt/conda/lib/python3.8/site-packages/urllib3/connection.py", line 174, in _new_conn
    conn = connection.create_connection(
  File "/opt/conda/lib/python3.8/site-packages/urllib3/util/connection.py", line 96, in create_connection
    raise err
  File "/opt/conda/lib/python3.8/site-packages/urllib3/util/connection.py", line 86, in create_connection
    sock.connect(sa)
ConnectionRefusedError: [Errno 111] Connection refused

During handling of the above exception, another exception occurred:

Traceback (most recent call last):
  File "/opt/conda/lib/python3.8/site-packages/urllib3/connectionpool.py", line 699, in urlopen
    httplib_response = self._make_request(
  File "/opt/conda/lib/python3.8/site-packages/urllib3/connectionpool.py", line 394, in _make_request
    conn.request(method, url, **httplib_request_kw)
  File "/opt/conda/lib/python3.8/site-packages/urllib3/connection.py", line 239, in request
    super(HTTPConnection, self).request(method, url, body=body, headers=headers)
  File "/opt/conda/lib/python3.8/http/client.py", line 1256, in request
    self._send_request(method, url, body, headers, encode_chunked)
  File "/opt/conda/lib/python3.8/http/client.py", line 1302, in _send_request
    self.endheaders(body, encode_chunked=encode_chunked)
  File "/opt/conda/lib/python3.8/http/client.py", line 1251, in endheaders
    self._send_output(message_body, encode_chunked=encode_chunked)
  File "/opt/conda/lib/python3.8/http/client.py", line 1011, in _send_output
    self.send(msg)
  File "/opt/conda/lib/python3.8/http/client.py", line 951, in send
    self.connect()
  File "/opt/conda/lib/python3.8/site-packages/urllib3/connection.py", line 205, in connect
    conn = self._new_conn()
  File "/opt/conda/lib/python3.8/site-packages/urllib3/connection.py", line 186, in _new_conn
    raise NewConnectionError(
urllib3.exceptions.NewConnectionError: <urllib3.connection.HTTPConnection object at 0x7f43ea27e910>: Failed to establish a new connection: [Errno 111] Connection refused

During handling of the above exception, another exception occurred:

Traceback (most recent call last):
  File "/opt/conda/lib/python3.8/site-packages/mlflow/utils/rest_utils.py", line 151, in http_request
    return _get_http_response_with_retries(
  File "/opt/conda/lib/python3.8/site-packages/mlflow/utils/rest_utils.py", line 91, in _get_http_response_with_retries
    return session.request(method, url, **kwargs)
  File "/opt/conda/lib/python3.8/site-packages/requests/sessions.py", line 542, in request
    resp = self.send(prep, **send_kwargs)
  File "/opt/conda/lib/python3.8/site-packages/requests/sessions.py", line 655, in send
    r = adapter.send(request, **kwargs)
  File "/opt/conda/lib/python3.8/site-packages/requests/adapters.py", line 439, in send
    resp = conn.urlopen(
  File "/opt/conda/lib/python3.8/site-packages/urllib3/connectionpool.py", line 783, in urlopen
    return self.urlopen(
  File "/opt/conda/lib/python3.8/site-packages/urllib3/connectionpool.py", line 783, in urlopen
    return self.urlopen(
  File "/opt/conda/lib/python3.8/site-packages/urllib3/connectionpool.py", line 783, in urlopen
    return self.urlopen(
  File "/opt/conda/lib/python3.8/site-packages/urllib3/connectionpool.py", line 758, in urlopen
    retries.sleep()
  File "/opt/conda/lib/python3.8/site-packages/urllib3/util/retry.py", line 414, in sleep
    self._sleep_backoff()
  File "/opt/conda/lib/python3.8/site-packages/urllib3/util/retry.py", line 398, in _sleep_backoff
    time.sleep(backoff)
  File "/opt/conda/lib/python3.8/site-packages/airflow/models/taskinstance.py", line 1563, in signal_handler
    raise AirflowException("Task received SIGTERM signal")
airflow.exceptions.AirflowException: Task received SIGTERM signal

During handling of the above exception, another exception occurred:

Traceback (most recent call last):
  File "/opt/conda/lib/python3.8/site-packages/airflow/operators/python.py", line 171, in execute
    return_value = self.execute_callable()
  File "/opt/conda/lib/python3.8/site-packages/airflow/operators/python.py", line 189, in execute_callable
    return self.python_callable(*self.op_args, **self.op_kwargs)
  File "/home/airflow/dags/Lead_scoring_training_pipeline/utils.py", line 144, in get_trained_model
    with mlflow.start_run(run_name=experiment) as mlrun:
  File "/opt/conda/lib/python3.8/site-packages/mlflow/tracking/fluent.py", line 318, in start_run
    active_run_obj = client.create_run(experiment_id=exp_id_for_run, tags=resolved_tags)
  File "/opt/conda/lib/python3.8/site-packages/mlflow/tracking/client.py", line 265, in create_run
    return self._tracking_client.create_run(experiment_id, start_time, tags)
  File "/opt/conda/lib/python3.8/site-packages/mlflow/tracking/_tracking_service/client.py", line 99, in create_run
    return self.store.create_run(
  File "/opt/conda/lib/python3.8/site-packages/mlflow/store/tracking/rest_store.py", line 170, in create_run
    response_proto = self._call_endpoint(CreateRun, req_body)
  File "/opt/conda/lib/python3.8/site-packages/mlflow/store/tracking/rest_store.py", line 56, in _call_endpoint
    return call_endpoint(self.get_host_creds(), endpoint, method, json_body, response_proto)
  File "/opt/conda/lib/python3.8/site-packages/mlflow/utils/rest_utils.py", line 253, in call_endpoint
    response = http_request(
  File "/opt/conda/lib/python3.8/site-packages/mlflow/utils/rest_utils.py", line 163, in http_request
    raise MlflowException("API request to %s failed with exception %s" % (url, e))
mlflow.exceptions.MlflowException: API request to http://0.0.0.0:6007/api/2.0/mlflow/runs/create failed with exception Task received SIGTERM signal
[2022-10-21 16:52:36,622] {taskinstance.py:1415} INFO - Marking task as FAILED. dag_id=Lead_scoring_training_pipeline, task_id=training_model, execution_date=20221021T165058, start_date=20221021T165221, end_date=20221021T165236
[2022-10-21 16:52:36,632] {standard_task_runner.py:92} ERROR - Failed to execute job 72 for task training_model (API request to http://0.0.0.0:6007/api/2.0/mlflow/runs/create failed with exception Task received SIGTERM signal; 5585)
[2022-10-21 16:52:36,659] {process_utils.py:75} INFO - Process psutil.Process(pid=5585, status='terminated', exitcode=1, started='16:52:20') (5585) terminated with exit code 1
