[2022-10-24 09:03:59,945] {taskinstance.py:1179} INFO - Dependencies all met for <TaskInstance: Lead_scoring_inference_pipeline.generating_models_prediction scheduled__2022-10-24T08:00:00+00:00 [queued]>
[2022-10-24 09:03:59,953] {taskinstance.py:1179} INFO - Dependencies all met for <TaskInstance: Lead_scoring_inference_pipeline.generating_models_prediction scheduled__2022-10-24T08:00:00+00:00 [queued]>
[2022-10-24 09:03:59,953] {taskinstance.py:1376} INFO - 
--------------------------------------------------------------------------------
[2022-10-24 09:03:59,953] {taskinstance.py:1377} INFO - Starting attempt 1 of 2
[2022-10-24 09:03:59,953] {taskinstance.py:1378} INFO - 
--------------------------------------------------------------------------------
[2022-10-24 09:03:59,964] {taskinstance.py:1397} INFO - Executing <Task(PythonOperator): generating_models_prediction> on 2022-10-24 08:00:00+00:00
[2022-10-24 09:03:59,974] {standard_task_runner.py:52} INFO - Started process 3767 to run task
[2022-10-24 09:03:59,980] {standard_task_runner.py:79} INFO - Running: ['airflow', 'tasks', 'run', 'Lead_scoring_inference_pipeline', 'generating_models_prediction', 'scheduled__2022-10-24T08:00:00+00:00', '--job-id', '213', '--raw', '--subdir', 'DAGS_FOLDER/Lead_scoring_inference_pipeline/.ipynb_checkpoints/lead_scoring_inference_pipeline-checkpoint.py', '--cfg-path', '/tmp/tmph82ylzn3', '--error-file', '/tmp/tmp2o8b6u0a']
[2022-10-24 09:03:59,981] {standard_task_runner.py:80} INFO - Job 213: Subtask generating_models_prediction
[2022-10-24 09:04:00,027] {task_command.py:371} INFO - Running <TaskInstance: Lead_scoring_inference_pipeline.generating_models_prediction scheduled__2022-10-24T08:00:00+00:00 [running]> on host 6b7947c6cb4e
[2022-10-24 09:04:00,078] {taskinstance.py:1589} INFO - Exporting the following env vars:
AIRFLOW_CTX_DAG_OWNER=airflow
AIRFLOW_CTX_DAG_ID=Lead_scoring_inference_pipeline
AIRFLOW_CTX_TASK_ID=generating_models_prediction
AIRFLOW_CTX_EXECUTION_DATE=2022-10-24T08:00:00+00:00
AIRFLOW_CTX_TRY_NUMBER=1
AIRFLOW_CTX_DAG_RUN_ID=scheduled__2022-10-24T08:00:00+00:00
[2022-10-24 09:04:00,079] {process_utils.py:125} INFO - Sending Signals.SIGTERM to group 3767. PIDs of all processes in the group: [3767]
[2022-10-24 09:04:00,080] {process_utils.py:80} INFO - Sending the signal Signals.SIGTERM to group 3767
[2022-10-24 09:04:00,596] {taskinstance.py:1561} ERROR - Received SIGTERM. Terminating subprocesses.
[2022-10-24 09:04:00,626] {taskinstance.py:1909} ERROR - Task failed with exception
Traceback (most recent call last):
  File "/opt/conda/lib/python3.8/site-packages/airflow/operators/python.py", line 171, in execute
    return_value = self.execute_callable()
  File "/opt/conda/lib/python3.8/site-packages/airflow/operators/python.py", line 189, in execute_callable
    return self.python_callable(*self.op_args, **self.op_kwargs)
  File "/home/Assignment/03_inference_pipeline/scripts/utils.py", line 119, in get_models_prediction
    X = __read_input_data(db_path, db_file_name, 'features')
  File "/home/Assignment/03_inference_pipeline/scripts/utils.py", line 43, in __read_input_data
    df = pd.read_sql('select * from '+ table_name, cnx)
  File "/opt/conda/lib/python3.8/site-packages/pandas/io/sql.py", line 566, in read_sql
    return pandas_sql.read_query(
  File "/opt/conda/lib/python3.8/site-packages/pandas/io/sql.py", line 2094, in read_query
    data = self._fetchall_as_list(cursor)
  File "/opt/conda/lib/python3.8/site-packages/pandas/io/sql.py", line 2108, in _fetchall_as_list
    result = cur.fetchall()
  File "/opt/conda/lib/python3.8/site-packages/airflow/models/taskinstance.py", line 1563, in signal_handler
    raise AirflowException("Task received SIGTERM signal")
airflow.exceptions.AirflowException: Task received SIGTERM signal
[2022-10-24 09:04:00,631] {taskinstance.py:1415} INFO - Marking task as UP_FOR_RETRY. dag_id=Lead_scoring_inference_pipeline, task_id=generating_models_prediction, execution_date=20221024T080000, start_date=20221024T090359, end_date=20221024T090400
[2022-10-24 09:04:00,638] {standard_task_runner.py:92} ERROR - Failed to execute job 213 for task generating_models_prediction (Task received SIGTERM signal; 3767)
[2022-10-24 09:04:00,654] {process_utils.py:75} INFO - Process psutil.Process(pid=3767, status='terminated', exitcode=1, started='09:03:59') (3767) terminated with exit code 1
